Workbook

Sheet Hypothèses
B2: ESTIMATION DU COÛT — PROJET D'ADRESSAGE DE MATAM (PHASE D'EXTENSION)
B3: Modèle éditable : modifiez les cellules en jaune pour recalculer automatiquement le coût estimé.
B5: A. Données de référence — Commune de Matam
B6: Paramètre | C6: Valeur | D6: Source / Hypothèse
B7: Superficie de Matam (km²) | C7: 35 | D7: Source : déclaration du président de la délégation spéciale de Matam, mars 2026 (Guinee7.com) ; la mairie de Matam indique 29,88 km² dans une publication antérieure — écart à clarifier
B8: Population de Matam, RGPH-4 (2025) | C8: 177271 | D8: Source : recensement général de la population et de l'habitation (RGPH-4), résultats publiés le 25 février 2026 (INS Guinée)
B9: Année du recensement de référence | C9: 2025 | D9: RGPH-4, 2025
B10: Année de calcul (aujourd'hui) | C10: 2026 | D10: Hypothèse — année en cours
B11: Taux de croissance démographique annuel estimé | C11: 0.03 | D11: Hypothèse à ajuster — croissance urbaine moyenne Conakry (appliquée seulement sur 1 an, le RGPH-4 étant déjà récent)
B12: Taille moyenne d'un ménage (personnes) | C12: 7.1 | D12: Dérivé des données officielles de la mairie de Matam (143 255 habitants / 20 133 ménages ≈ 7,1) — plus précis que la moyenne urbaine générique utilisée pour Kaloum
B13: Bâtiments non résidentiels en % des bâtiments résidentiels | C13: 0.18 | D13: Hypothèse — Matam est une commune davantage résidentielle que Kaloum (centre administratif) ; activités commerciales concentrées autour des marchés de Bonfi et Coléah
B15: B. Estimation du nombre de bâtiments/unités à adresser
B16: Paramètre | C16: Valeur (calculée) | D16: Formule / logique
B17: Population estimée de Matam en 2026 | C17: =C8*(1+C11)^(C10-C9) -> 182589.13 | D17: Formule : Population 2014 × (1 + taux de croissance) ^ nombre d'années
B18: Ménages estimés (bâtiments résidentiels) | C18: =C17/C12 -> 25716.779 | D18: Formule : Population estimée / taille moyenne du ménage
B19: Total bâtiments/unités à adresser (résidentiel + non résidentiel) | C19: =C18*(1+C13) -> 30345.799 | D19: Formule : Ménages × (1 + % non résidentiel)
B21: C. Référence de coût unitaire — Projet d'Adressage du District d'Abidjan (PADA)
B22: Paramètre | C22: Valeur | D22: Source / Hypothèse
B23: Budget total du PADA (FCFA) | C23: 10000000000 | D23: Source : KOACI, financement de 10 milliards FCFA annoncé au lancement du PADA
B24: Unités d'occupation projetées (PADA) | C24: 348216 | D24: Source : KOACI, 348 216 unités d'occupation projetées pour le PADA
B25: Taux de change FCFA → USD (approx.) | C25: 600 | D25: Hypothèse — parité FCFA/USD approximative (le FCFA est arrimé à l'euro)
B26: Taux de change USD → GNF | C26: 8760 | D26: Source : cours de change moyen USD/GNF, juillet 2026
B27: Coût moyen par unité — référence PADA Abidjan (FCFA, indicatif) | C27: =C23/C24 -> 28717.807 | D27: Référence contextuelle uniquement (PADA Abidjan) — ne sert plus au calcul ci-dessous
B28: Coût moyen par unité d'occupation (USD) | C28: 55 | D28: Modifiable directement — coût unitaire retenu pour Matam (référence PADA Abidjan ≈ 48 $, ajustable selon votre propre estimation)
B30: D. Coût total estimé — Phase d'extension Matam
B31: Paramètre | C31: Valeur (calculée) | D31: Formule / logique
B32: Coût total estimé (USD) | C32: =C19*C28 -> 1669018.9 | D32: Formule : Total bâtiments × coût moyen par unité (USD)
B33: Coût total estimé (GNF) | C33: =C32*C26 -> 1.4620606e+10 | D33: Formule : Coût total USD × taux USD-GNF
B34: Coût par habitant estimé (GNF) | C34: =C33/C17 -> 80073.803 | D34: Formule : Coût total (GNF) / population estimée
B36: ⚠ Ceci est une estimation d'ordre de grandeur basée sur un coût moyen observé à Abidjan, projet de contexte comparable. Un chiffrage ferme nécessite un recensement de terrain à Matam et un appel d'offres auprès de prestataires SIG/géomatique.

Sheet Budget par poste
B2: RÉPARTITION BUDGÉTAIRE PAR POSTE — PHASE D'EXTENSION MATAM
B3: La répartition (%) en jaune est modifiable ; elle doit totaliser 100 % sur les postes de base. Un ajustement pour le renforcement de la signalétique et une provision pour imprévus s'ajoutent ensuite.
B5: Référence : coût de base estimé (onglet Hypothèses, avant ajustement signalétique) | C5: =Hypothèses!C32 -> 1669018.9 | D5: =Hypothèses!C33 -> 1.4620606e+10
B7: Poste de dépense | C7: % du total | D7: Montant (USD) | E7: Montant (GNF)
B8: Cartographie et collecte de données (imagerie satellite/drone, relevés GPS terrain) | C8: 0.25 | D8: =C8*$C$5 -> 417254.74 | E8: =C8*$D$5 -> 3.6551515e+09
B9: Répertoire toponymique et validation communale des noms de voies | C9: 0.05 | D9: =C9*$C$5 -> 83450.947 | E9: =C9*$D$5 -> 7.310303e+08
B10: Enquête et numérotation des bâtiments (système métrique) | C10: 0.2 | D10: =C10*$C$5 -> 333803.79 | E10: =C10*$D$5 -> 2.9241212e+09
B11: Base de données SIG et portail numérique | C11: 0.15 | D11: =C11*$C$5 -> 250352.84 | E11: =C11*$D$5 -> 2.1930909e+09
B12: Fabrication et pose de la signalétique (plaques rues et bâtiments) | C12: 0.2 | D12: =C12*$C$5 -> 333803.79 | E12: =C12*$D$5 -> 2.9241212e+09
B13: Formation des agents communaux et sensibilisation des populations | C13: 0.05 | D13: =C13*$C$5 -> 83450.947 | E13: =C13*$D$5 -> 7.310303e+08
B14: Coordination et suivi-évaluation | C14: 0.1 | D14: =C14*$C$5 -> 166901.89 | E14: =C14*$D$5 -> 1.4620606e+09
B15: SOUS-TOTAL (postes de base) | C15: =SUM(C8:C14) -> 1 | D15: =SUM(D8:D14) -> 1669018.9 | E15: =SUM(E8:E14) -> 1.4620606e+10
B17: Ajustement — renforcement de la signalétique (4 poteaux par intersection au lieu de 2) | D17: ='Équipements et prestataires'!F21+'Équipements et prestataires'!F22-D12 -> 12545.405 | E17: ='Équipements et prestataires'!E21+'Équipements et prestataires'!E22-E12 -> 1.0989775e+08
B18: Ajustement — venelles piétonnes et bâtiments multi-niveaux (signalétique complémentaire) | D18: ='Équipements et prestataires'!F62 -> 6481.1644 | E18: ='Équipements et prestataires'!E62 -> 56775000
B20: TOTAL (avant provision pour imprévus) | D20: =D15+D17+D18 -> 1688045.5 | E20: =E15+E17+E18 -> 1.4787279e+10
B22: Provision pour imprévus, retards et fluctuation des coûts | C22: 0.18 | D22: =C22*D20 -> 303848.19 | E22: =C22*E20 -> 2.6617102e+09
B23: BUDGET TOTAL AVEC PROVISION POUR IMPRÉVUS | C23: =1+C22 -> 1.18 | D23: =D20+D22 -> 1991893.7 | E23: =E20+E22 -> 1.7448989e+10
B25: Note : cette clé de répartition (%) est une hypothèse indicative fondée sur la structure de coûts habituelle des projets d'adressage comparables, à ajuster après devis des prestataires. L'ajustement signalétique reflète le passage à 4 poteaux par intersection (au lieu de 2) dans l'onglet Équipements et prestataires, qui donne un chiffrage plus précis que l'allocation forfaitaire de 20 % ci-dessus. La provision pour imprévus (15 à 20 % recommandé, 18 % retenu ici) couvre les retards de calendrier, les écarts de mesure sur le terrain et la fluctuation des coûts (change USD/GNF, prix des matériaux) ; elle s'applique au-dessus du budget ajusté.

Sheet Budget (approche ascendante)
B2: BUDGET — APPROCHE ASCENDANTE (BOTTOM-UP) — PHASE D'EXTENSION MATAM
B3: Scénario alternatif : le total est ici la somme réelle du personnel et des équipements/prestataires prévus, plutôt qu'une estimation par unité (55 $/bâtiment). Ne remplace pas l'onglet « Budget par poste » — sert de comparaison.
B7: Poste | D7: Montant (USD) | E7: Montant (GNF)
B9: Ressources humaines (onglet Ressources humaines, total) | D9: ='Ressources humaines'!J16 -> 182648.4 | E9: ='Ressources humaines'!I16 -> 1600000000
B10: Équipements + Prestataires + Ajustements (onglet Équipements et prestataires, total A+B+C) | D10: ='Équipements et prestataires'!F64 -> 451834.93 | E10: ='Équipements et prestataires'!E64 -> 3.9580739e+09
B12: SOUS-TOTAL (personnel + équipements + prestataires) | D12: =SUM(D9:D10) -> 634483.33 | E12: =SUM(E9:E10) -> 5.5580739e+09
B14: Provision pour imprévus, retards et fluctuation des coûts | C14: 0.18 | D14: =C14*D12 -> 114207 | E14: =C14*E12 -> 1.0004533e+09
B16: BUDGET TOTAL (APPROCHE ASCENDANTE) | C16: =1+C14 -> 1.18 | D16: =D12+D14 -> 748690.33 | E16: =E12+E14 -> 6.5585273e+09
B19: Comparaison avec l'approche descendante (onglet Budget par poste)
B20: Budget total — approche descendante (population × coût unitaire) | D20: ='Budget par poste'!D23 -> 1991893.7 | E20: ='Budget par poste'!E23 -> 1.7448989e+10
B21: Budget total — approche ascendante (ce scénario) | D21: =D16 -> 748690.33 | E21: =E16 -> 6.5585273e+09
B22: Écart (descendant − ascendant) | D22: =D20-D21 -> 1243203.4 | E22: =E20-E21 -> 1.0890462e+10
B23: Écart en % (par rapport à l'approche descendante) | C23: =D22/D20 -> 0.62413139
B25: Note : ce scénario totalise ce qui est explicitement chiffré dans les onglets Ressources humaines et Équipements et prestataires. Il ne comprend pas de marge bénéficiaire ni de frais de structure/siège non listés ailleurs.

Sheet Ressources humaines
B2: RESSOURCES HUMAINES — PHASE D'EXTENSION MATAM
B3: Effectifs et salaires (en jaune) modifiables. Le coût total se recalcule et peut être comparé au chiffrage par poste de l'onglet précédent.
B5: Poste | C5: Effectif | D5: Coût mensuel (GNF/personne) | E5: Durée (mois) | F5: Coût total /personne (GNF) | G5: Coût total /personne (USD) | H5: Type | I5: Coût total (GNF) | J5: Coût total (USD)
B6: Chef de projet | C6: 1 | D6: 15000000 | E6: 12 | F6: =D6*E6 -> 180000000 | G6: =F6/Hypothèses!$C$26 -> 20547.945 | H6: Permanent | I6: =C6*D6*E6 -> 180000000 | J6: =I6/Hypothèses!$C$26 -> 20547.945
B7: Responsable SIG / géomaticien en chef | C7: 1 | D7: 12000000 | E7: 12 | F7: =D7*E7 -> 144000000 | G7: =F7/Hypothèses!$C$26 -> 16438.356 | H7: Permanent | I7: =C7*D7*E7 -> 144000000 | J7: =I7/Hypothèses!$C$26 -> 16438.356
B8: Techniciens SIG / cartographes | C8: 4 | D8: 6000000 | E8: 12 | F8: =D8*E8 -> 72000000 | G8: =F8/Hypothèses!$C$26 -> 8219.1781 | H8: Permanent | I8: =C8*D8*E8 -> 288000000 | J8: =I8/Hypothèses!$C$26 -> 32876.712
B9: Développeurs informatiques (base de données/portail) | C9: 2 | D9: 7000000 | E9: 8 | F9: =D9*E9 -> 56000000 | G9: =F9/Hypothèses!$C$26 -> 6392.6941 | H9: Permanent | I9: =C9*D9*E9 -> 112000000 | J9: =I9/Hypothèses!$C$26 -> 12785.388
B10: Chefs d'équipe de terrain (superviseurs) | C10: 3 | D10: 5000000 | E10: 9 | F10: =D10*E10 -> 45000000 | G10: =F10/Hypothèses!$C$26 -> 5136.9863 | H10: Permanent | I10: =C10*D10*E10 -> 135000000 | J10: =I10/Hypothèses!$C$26 -> 15410.959
B11: Agents enquêteurs (numérotation + GPS), en 7 équipes de 2 | C11: 14 | D11: 3000000 | E11: 9 | F11: =D11*E11 -> 27000000 | G11: =F11/Hypothèses!$C$26 -> 3082.1918 | H11: Temporaire | I11: =C11*D11*E11 -> 378000000 | J11: =I11/Hypothèses!$C$26 -> 43150.685
B12: Agents de sensibilisation communautaire | C12: 6 | D12: 2500000 | E12: 9 | F12: =D12*E12 -> 22500000 | G12: =F12/Hypothèses!$C$26 -> 2568.4932 | H12: Temporaire | I12: =C12*D12*E12 -> 135000000 | J12: =I12/Hypothèses!$C$26 -> 15410.959
B13: Personnel administratif et financier | C13: 2 | D13: 4000000 | E13: 12 | F13: =D13*E13 -> 48000000 | G13: =F13/Hypothèses!$C$26 -> 5479.4521 | H13: Permanent | I13: =C13*D13*E13 -> 96000000 | J13: =I13/Hypothèses!$C$26 -> 10958.904
B14: Chauffeurs / logistique | C14: 2 | D14: 2500000 | E14: 12 | F14: =D14*E14 -> 30000000 | G14: =F14/Hypothèses!$C$26 -> 3424.6575 | H14: Permanent | I14: =C14*D14*E14 -> 60000000 | J14: =I14/Hypothèses!$C$26 -> 6849.3151
B15: Personnel de renfort / réserve (mobilisable si le terrain s'avère plus complexe que prévu) | C15: 4 | D15: 3000000 | E15: 6 | F15: =D15*E15 -> 18000000 | G15: =F15/Hypothèses!$C$26 -> 2054.7945 | H15: Temporaire (réserve) | I15: =C15*D15*E15 -> 72000000 | J15: =I15/Hypothèses!$C$26 -> 8219.1781
B16: TOTAL RESSOURCES HUMAINES | I16: =SUM(I6:I15) -> 1600000000 | J16: =SUM(J6:J15) -> 182648.4
B17: Coût moyen par personne (toute l'équipe) | F17: =I16/SUM(C6:C15) -> 41025641 | G17: =J16/SUM(C6:C15) -> 4683.2924
B19: Note : l'équipe de pose de signalétique (4 à 6 personnes) est généralement sous-traitée à une entreprise locale et déjà comptabilisée dans le poste « signalétique » de l'onglet Budget par poste — elle n'est pas dupliquée ici. Le spécialiste toponymie et l'expert juridique interviennent en mission ponctuelle (honoraires forfaitaires, non inclus dans cette masse salariale mensuelle). Le personnel de renfort est une réserve de capacité mobilisable si le volume de terrain (nombre de voies, densité du bâti) s'avère supérieur aux hypothèses de départ ; son coût est déjà intégré au total ci-dessus.
B21: Comparaison avec l'estimation par poste (onglet précédent)
B22: Masse salariale totale (GNF / USD), calculée ci-dessus | C22: =I16 -> 1600000000 | D22: =J16 -> 182648.4
B23: Part de la masse salariale dans le budget total estimé | C23: =J16/Hypothèses!C32 -> 0.10943459

Sheet Équipements et prestataires
B2: ÉQUIPEMENTS ET PRESTATAIRES DE SERVICES — PHASE D'EXTENSION MATAM
B3: Quantités et coûts unitaires (en jaune) modifiables. Références liées au nombre de bâtiments, de voies et d'intersections estimé.
B5: Nombre de voies estimé à Matam (hypothèse à confirmer par la cartographie) | C5: 350 | D5: Hypothèse dérivée des 24 quartiers / 103 secteurs de Matam (≈3,4 voies par secteur) et de sa superficie de 35 km², à affiner par imagerie/terrain
B6: Intersections par voie (moyenne, croisements le long d'une rue) | C6: 3 | D6: Hypothèse — tissu urbain de Matam (mix résidentiel/commercial), à affiner par la cartographie
B7: Poteaux/plaques par intersection | C7: 4 | D7: 2 = un poteau par coin opposé (norme courante) ; jusqu'à 4 pour une visibilité renforcée dans toutes les directions
B8: Nombre d'intersections estimé | C8: =ROUND(C5*C6/2,0) -> 525 | D8: Formule : (nombre de voies × intersections par voie) / 2 — la division par 2 évite de compter deux fois chaque croisement (partagé par deux rues)
B9: Nombre de poteaux/plaques de rue nécessaires | C9: =C8*C7 -> 2100 | D9: Formule : nombre d'intersections × poteaux par intersection
B11: A. Équipements (matériel à acquérir)
B12: Article | C12: Quantité | D12: Coût unitaire (GNF) | E12: Coût total (GNF) | F12: Coût total (USD)
B13: Récepteurs GPS de précision (sub-métrique) | C13: 12 | D13: 4500000 | E13: =C13*D13 -> 54000000 | F13: =E13/Hypothèses!$C$26 -> 6164.3836
B14: Tablettes de terrain robustes (collecte mobile, Android) | C14: 14 | D14: 2200000 | E14: =C14*D14 -> 30800000 | F14: =E14/Hypothèses!$C$26 -> 3515.9817
B15: Ordinateurs portables (équipe SIG / bureau) | C15: 8 | D15: 6500000 | E15: =C15*D15 -> 52000000 | F15: =E15/Hypothèses!$C$26 -> 5936.0731
B16: Licences logiciels SIG professionnels (ou QGIS gratuit + support payant) | C16: 1 | D16: 25000000 | E16: =C16*D16 -> 25000000 | F16: =E16/Hypothèses!$C$26 -> 2853.8813
B17: Serveur / hébergement cloud pour la base de données SIG (12 mois) | C17: 1 | D17: 30000000 | E17: =C17*D17 -> 30000000 | F17: =E17/Hypothèses!$C$26 -> 3424.6575
B18: Imprimante/traceur grand format pour cartes | C18: 1 | D18: 8000000 | E18: =C18*D18 -> 8000000 | F18: =E18/Hypothèses!$C$26 -> 913.24201
B19: Location de véhicules 4x4 / motos pour les équipes de terrain (9 mois) | C19: 3 | D19: 27000000 | E19: =C19*D19 -> 81000000 | F19: =E19/Hypothèses!$C$26 -> 9246.5753
B20: Mobilier et équipement de bureau du projet | C20: 1 | D20: 15000000 | E20: =C20*D20 -> 15000000 | F20: =E20/Hypothèses!$C$26 -> 1712.3288
B21: Plaques de numérotation des bâtiments (fabrication, gravure) | C21: =Hypothèses!$C$19 -> 30345.799 | D21: 55000 | E21: =C21*D21 -> 1.6690189e+09 | F21: =E21/Hypothèses!$C$26 -> 190527.28
B22: Plaques de rue et poteaux/supports (fabrication et pose, par intersection) | C22: =C9 -> 2100 | D22: 650000 | E22: =C22*D22 -> 1365000000 | F22: =E22/Hypothèses!$C$26 -> 155821.92
B23: SOUS-TOTAL A — ÉQUIPEMENTS | E23: =SUM(E13:E22) -> 3.3298189e+09 | F23: =SUM(F13:F22) -> 380116.32
B25: B. Prestataires de services (sous-traitance)
B26: Article | C26: Unité | D26: Coût unitaire (GNF) | E26: Coût total (GNF) | F26: Coût total (USD)
B27: Imagerie satellite / prises de vue par drone (couverture de Matam) | C27: 1 | D27: 80000000 | E27: =C27*D27 -> 80000000 | F27: =E27/Hypothèses!$C$26 -> 9132.4201
B28: Bureau d'études SIG / géomatique — assistance technique méthodologique | C28: 1 | D28: 150000000 | E28: =C28*D28 -> 150000000 | F28: =E28/Hypothèses!$C$26 -> 17123.288
B29: Entreprise de fabrication et pose de la signalétique — supervision qualité | C29: 1 | D29: 40000000 | E29: =C29*D29 -> 40000000 | F29: =E29/Hypothèses!$C$26 -> 4566.21
B30: Développement du portail web / application SIG (si sous-traité) | C30: 1 | D30: 60000000 | E30: =C30*D30 -> 60000000 | F30: =E30/Hypothèses!$C$26 -> 6849.3151
B31: Impression de supports de sensibilisation (affiches, dépliants) | C31: 1 | D31: 15000000 | E31: =C31*D31 -> 15000000 | F31: =E31/Hypothèses!$C$26 -> 1712.3288
B32: Audit qualité et évaluation indépendante de la phase pilote | C32: 1 | D32: 25000000 | E32: =C32*D32 -> 25000000 | F32: =E32/Hypothèses!$C$26 -> 2853.8813
B33: Consultance ponctuelle d'experts internationaux (jours-expert, mobilisable au besoin) | C33: 20 | D33: 7884000 | E33: =C33*D33 -> 157680000 | F33: =E33/Hypothèses!$C$26 -> 18000
B34: Frais de voyage et indemnités des experts internationaux (mobilisable au besoin) | C34: 1 | D34: 43800000 | E34: =C34*D34 -> 43800000 | F34: =E34/Hypothèses!$C$26 -> 5000
B35: SOUS-TOTAL B — PRESTATAIRES DE SERVICES | E35: =SUM(E27:E34) -> 571480000 | F35: =SUM(F27:F34) -> 65237.443
B37: TOTAL ÉQUIPEMENTS + PRESTATAIRES (A + B) | E37: =E23+E35 -> 3.9012989e+09 | F37: =F23+F35 -> 445353.76
B39: Part de ce total dans le budget global estimé (onglet Hypothèses) | C39: =F37/Hypothèses!C32 -> 0.26683565
B41: Note : les coûts unitaires ci-dessus sont des hypothèses de travail à confirmer par des devis réels de fournisseurs et prestataires locaux et régionaux. La location de véhicules est privilégiée à l'achat pour une phase pilote de durée limitée. Le nombre de poteaux/plaques de rue est désormais calculé par intersection (nombre de voies × intersections par voie ÷ 2, puis × poteaux par intersection) plutôt qu'une simple plaque par rue, ce qui reflète mieux la réalité du terrain. La consultance d'experts internationaux (20 jours-expert à titre indicatif, environ 900 $/jour, plus frais de voyage) est une réserve mobilisable au besoin ; elle n'est pas systématiquement dépensée dans son intégralité.
B43: C. Ajustements complémentaires — venelles piétonnes et bâtiments multi-niveaux
B44: Hypothèses (en jaune) modifiables, sur le même principe que les paramètres ci-dessus.
B46: Estimation du nombre de venelles piétonnes
B47: Nombre de voies estimé à Matam (repris ci-dessus) | C47: =C5 -> 350 | D47: Référence : cellule C5 de cet onglet
B48: Voies desservant au moins une venelle (zone non lotie) | C48: 0.3 | D48: Hypothèse — Matam comporte des zones non loties importantes (Coléah, Boussoura...), part plus élevée qu'à Kaloum
B49: Nombre moyen de venelles par voie concernée | C49: 1.3 | D49: Hypothèse — plusieurs venelles peuvent partir d'une même voie
...

Sheet Marge (usage interne)
B2: MARGE BÉNÉFICIAIRE — USAGE INTERNE (NE PAS TRANSMETTRE AU GOUVERNEMENT)
B3: Cet onglet est un outil de pilotage pour votre entreprise. La note de proposition envoyée au gouvernement ne doit présenter que le coût du projet, pas votre marge.
B5: Coût total du projet (référence : onglet Hypothèses) | C5: USD | D5: GNF
B6: Coût total estimé du projet (avec provision pour imprévus) | C6: ='Budget par poste'!D22 -> 303848.19 | D6: ='Budget par poste'!E22 -> 2.6617102e+09
B8: Taux de marge retenu pour le scénario recommandé | C8: 0.15 | D8: Modifiable — recommandé 15 à 20 % pour un premier contrat pilote avec risque de préfinancement
B10: Scénarios de marge (majoration sur coût)
B11: Scénario | C11: Taux de marge | D11: Profit (USD) | E11: Profit (GNF) | F11: Prix total à facturer (USD) | G11: Prix total à facturer (GNF)
B12: Prudent (grand contractant, faible risque) | C12: 0.1 | D12: =$C$6*C12 -> 30384.819 | E12: =$D$6*C12 -> 2.6617102e+08 | F12: =$C$6+D12 -> 334233.01 | G12: =$D$6+E12 -> 2.9278812e+09
B13: Recommandé (PME, premier contrat, risque de préfinancement) | C13: 0.15 | D13: =$C$6*C13 -> 45577.229 | E13: =$D$6*C13 -> 3.9925653e+08 | F13: =$C$6+D13 -> 349425.42 | G13: =$D$6+E13 -> 3.0609667e+09
B14: Ambitieux (risque élevé, forte valeur ajoutée technique) | C14: 0.2 | D14: =$C$6*C14 -> 60769.639 | E14: =$D$6*C14 -> 5.3234203e+08 | F14: =$C$6+D14 -> 364617.83 | G14: =$D$6+E14 -> 3.1940522e+09
B16: Note : ceci est une majoration sur coût (« markup »). Prix facturé = Coût × (1 + marge). Si vous devez présenter une marge en % du prix de vente (« marge commerciale »), utilisez plutôt Prix = Coût / (1 − marge) — les deux méthodes donnent des taux différents pour un même profit visé.
B18: Facteurs qui justifient une marge plus élevée que sur un marché mature :
B19: • Préfinancement : l'État paie souvent avec retard ; votre entreprise avance salaires, équipements et prestataires.
B20: • Risque de change : coûts en partie liés au dollar (équipements importés), recettes en GNF.
B21: • Projet inédit en Guinée : pas de références locales directes, courbe d'apprentissage sur la méthodologie.
B22: • Réputation : un pilote réussi ouvre la voie à l'extension aux 4 autres communes — valeur au-delà du seul contrat pilote.
