Workbook

Sheet Synthèse
A1: Projet national d'adressage de Conakry
A2: Phase d'extension — Commune de Dixinn
A3: Modèle de calcul — synthèse (Méridien Aménagement & Ingénierie)
A5: Bâti et voirie
A6: Bâtiments estimés (2026) | B6: =BATIMENTS -> 42495 | C6: Hypothèses — population projetée / taille du ménage
A7: Quartiers | B7: =QUARTIERS_DIXINN -> 21
A8: Voies estimées | B8: =VOIES -> 482
A9: Intersections estimées | B9: =INTERSECTIONS -> 723
A10: Poteaux / plaques de rue | B10: =POTEAUX -> 2890
A12: Budget
A13: Sous-total A+B avant provisions (USD) | B13: =Budget!C18 -> 3014033
A14: Sous-total A+B avant provisions (GNF) | B14: =Budget!D18 -> 26421013278
A15: Provision pour imprévus (USD) | B15: =Budget!C19 -> 542526
A16: Provision pour retards de calendrier (USD) | B16: =Budget!C23 -> 145217
A17: BUDGET TOTAL DU PROJET (USD) | B17: =Budget!C25 -> 3701776
A18: BUDGET TOTAL DU PROJET (GNF) | B18: =Budget!D25 -> 32449768416
A19: Ressources humaines
A20: Effectif total mobilisé | B20: =RH!D27 -> 180
A21: Masse salariale estimée (USD) | B21: =RH!D33 -> 842416
A23: Comparaison avec le pilote de Kaloum
A24: Facteur d'échelle (bâtiments Dixinn / Kaloum) | B24: =SCALE -> 2.1904639
A25: Budget Kaloum (référence, avant provision, USD) | B25: =KAL_CARTO+KAL_TOPO+KAL_ENQ+KAL_SIG+KAL_SIGN+KAL_FORM+KAL_COORD+KAL_AJUST -> 1075000
A28: Comment utiliser ce classeur
A29: 1. Feuille « Hypothèses » : toutes les valeurs modifiables (fond jaune, texte bleu) — population, taux de
A30: croissance, taux de change, multiplicateurs budgétaires, chiffrage de référence de Kaloum.
A31: 2. Feuilles « Budget », « RH », « Équipements » : calculs détaillés, entièrement formulés à partir des
A32: Hypothèses — aucune valeur n'y est codée en dur.
A33: 3. Modifier une hypothèse (ex. population, taux de croissance) recalcule automatiquement l'ensemble du
A34: classeur, y compris cette synthèse.
A35: 4. Les chiffres de ce modèle correspondent à ceux de la note de proposition Word (légères différences
A36: d'arrondi possibles, la note utilisant des valeurs arrondies pour la lecture).

Sheet Hypothèses
A1: Modèle de calcul — Projet d'adressage de Dixinn
A2: Cellules en bleu sur fond jaune = hypothèses modifiables. Le reste recalcule automatiquement.
A4: Démographie et bâti — Dixinn
A5: Population de Dixinn (recensement 2014) | B5: 137287 | C5: habitants | D5: Source : RGPH3 2014 / INS Guinée (Wikipédia, en.wikipedia.org/wiki/Dixinn)
A6: Taux de croissance urbaine annuel | B6: 0.04 | C6: %/an | D6: Calibré pour reproduire la projection 2026 utilisée dans la note Kaloum
A7: Horizon de projection (2014 → 2026) | B7: 12 | C7: années
A8: Taille moyenne du ménage | B8: 6 | C8: personnes/ménage
A9: Majoration bâtiments non résidentiels | B9: 1.16 | C9: facteur | D9: Écarts commerces / bureaux / équipements en sus des logements
A10: Nombre de quartiers de Dixinn | B10: 21 | C10: quartiers | D10: Source : Annuaire statistique INS Guinée / liste des quartiers de Dixinn
A12: Référence — phase pilote de Kaloum (déjà chiffrée)
A13: Bâtiments recensés — Kaloum | B13: 19400 | C13: bâtiments
A14: Quartiers — Kaloum | B14: 11 | C14: quartiers
A15: Voies estimées — Kaloum | B15: 220 | C15: voies
A16: Intersections estimées — Kaloum | B16: 330 | C16: intersections
A17: Poteaux/plaques de rue — Kaloum | B17: 1320 | C17: poteaux
A18: Poteaux par intersection | B18: 4 | C18: poteaux/intersection | D18: Un poteau par coin de rue
A20: Change et provision
A21: Taux de change USD / GNF | B21: 8766 | C21: GNF pour 1 $ | D21: Dérivé du chiffrage de la note Kaloum (1 076 000 $ ≈ 9,43 Mds GNF)
A22: Taux de provision pour imprévus | B22: 0.18 | C22: %
A24: Multiplicateurs budgétaires — postes semi-fixes (vs Kaloum)
A25: Répertoire toponymique et validation communale | B25: 1.3 | C25: × | D25: Méthodologie déjà établie avec le pilote ; hausse liée au nb de quartiers
A26: Base de données SIG et portail numérique | B26: 0.5 | C26: × | D26: Plateforme déjà développée pour Kaloum ; coût marginal d'extension
A27: Formation des agents et sensibilisation | B27: 1.5 | C27: × | D27: Lié au nombre de quartiers plutôt qu'au nombre de bâtiments
A28: Coordination et suivi-évaluation | B28: 1.3 | C28: × | D28: Structure de pilotage déjà en place, renforcement partiel
A30: Budget de référence — phase pilote Kaloum (USD, avant provision)
A31: Cartographie et collecte de données | B31: 266000 | C31: $
A32: Répertoire toponymique et validation communale | B32: 53000 | C32: $
A33: Enquête et numérotation des bâtiments | B33: 213000 | C33: $
A34: Base de données SIG et portail numérique | B34: 160000 | C34: $
A35: Fabrication et pose de la signalétique | B35: 213000 | C35: $
A36: Formation des agents et sensibilisation | B36: 53000 | C36: $
A37: Coordination et suivi-évaluation | B37: 106000 | C37: $
A38: Ajustement — renforcement de la signalétique | B38: 11000 | C38: $
A40: Résultats calculés
A41: Population de Dixinn projetée (2026) | B41: =POP2014*(1+GROWTH)^YEARS -> 219800.91 | C41: habitants
A42: Bâtiments totaux estimés (2026) | B42: =ROUND(POP2026/HHSIZE*NONRES,0) -> 42495 | C42: bâtiments
A43: Facteur d'échelle vs Kaloum (bâtiments) | B43: =BATIMENTS/BAT_KALOUM -> 2.1904639 | C43: ×
A44: Poteaux / plaques de rue estimés | B44: =ROUND(POTEAUX_KALOUM*SCALE/10,0)*10 -> 2890 | C44: poteaux
A45: Intersections estimées | B45: =ROUND(POTEAUX/POT_PAR_INTER,0) -> 723 | C45: intersections
A46: Voies estimées | B46: =ROUND(INTERSECTIONS/(INTERS_KALOUM/VOIES_KALOUM),0) -> 482 | C46: voies
...

Sheet Budget
A1: Budget estimatif — phase d'extension à Dixinn
A3: A. Postes opérationnels (dérivés du chiffrage du pilote de Kaloum)
A4: Poste de dépense | B4: Formule (base Kaloum) | C4: Montant (USD) | D4: Montant (GNF) | E4: Origine du chiffre
A5: Cartographie et collecte de données | B5: KAL_CARTO × SCALE | C5: =ROUND(KAL_CARTO*SCALE,0) -> 582663 | D5: =C5*FX_RATE -> 5107623858 | E5: Poste variable — proportionnel au nombre de bâtiments
A6: Répertoire toponymique et validation communale | B6: KAL_TOPO × MULT_TOPO | C6: =ROUND(KAL_TOPO*MULT_TOPO,0) -> 68900 | D6: =C6*FX_RATE -> 603977400 | E6: Poste semi-fixe — voir multiplicateur en Hypothèses
A7: Enquête et numérotation des bâtiments | B7: KAL_ENQ × SCALE | C7: =ROUND(KAL_ENQ*SCALE,0) -> 466569 | D7: =C7*FX_RATE -> 4089943854 | E7: Poste variable — proportionnel au nombre de bâtiments
A8: Base de données SIG et portail numérique | B8: KAL_SIG × MULT_SIG | C8: =ROUND(KAL_SIG*MULT_SIG,0) -> 80000 | D8: =C8*FX_RATE -> 701280000 | E8: Réutilisation de la plateforme développée pour Kaloum
A9: Fabrication et pose de la signalétique | B9: KAL_SIGN × SCALE | C9: =ROUND(KAL_SIGN*SCALE,0) -> 466569 | D9: =C9*FX_RATE -> 4089943854 | E9: Poste variable — proportionnel au nombre de bâtiments/poteaux
A10: Formation des agents et sensibilisation | B10: KAL_FORM × MULT_FORM | C10: =ROUND(KAL_FORM*MULT_FORM,0) -> 79500 | D10: =C10*FX_RATE -> 696897000 | E10: Poste semi-fixe — lié au nombre de quartiers
A11: Coordination et suivi-évaluation | B11: KAL_COORD × MULT_COORD | C11: =ROUND(KAL_COORD*MULT_COORD,0) -> 137800 | D11: =C11*FX_RATE -> 1207954800 | E11: Poste semi-fixe — structure de pilotage déjà en place
A12: Ajustement — renforcement de la signalétique | B12: KAL_AJUST × SCALE | C12: =ROUND(KAL_AJUST*SCALE,0) -> 24095 | D12: =C12*FX_RATE -> 211216770 | E12: Poste variable — proportionnel au nombre de poteaux
A14: B. Renforts demandés — main d'œuvre × 3 et équipements × 2 (coût incrémental)
A15: Renfort main d'œuvre terrain (facteur × 3 vs plan de base) | B15: KAL_ENQ × SCALE × (MULT_MO − 1) | C15: =ROUND(KAL_ENQ*SCALE*(MULT_MO-1),0) -> 933138 | D15: =C15*FX_RATE -> 8179887708 | E15: Coût additionnel des 2 x effectifs terrain supplémentaires (cf. feuille RH)
A16: Renfort équipements techniques (facteur × 2 vs plan de base) | B16: KAL_CARTO × SCALE × PART_EQUIP_CARTO × (MULT_EQUIP − 1) | C16: =ROUND(KAL_CARTO*SCALE*PART_EQUIP_CARTO*(MULT_EQUIP-1),0) -> 174799 | D16: =C16*FX_RATE -> 1532288034 | E16: Coût additionnel du doublement des GPS, tablettes, ordinateurs et véhicules (cf. feuille Équipements)
A18: SOUS-TOTAL A + B (avant provisions) | C18: =SUM(C5:C12)+SUM(C15:C16) -> 3014033 | D18: =SUM(D5:D12)+SUM(D15:D16) -> 26421013278
A19: Provision pour imprévus (coûts/quantités) | B19: Sous-total × PROVISION_RATE | C19: =ROUND(C18*PROVISION_RATE,0) -> 542526 | D19: =C19*FX_RATE -> 4755782916 | E19: Taux modifiable en Hypothèses (fourchette usuelle 15-20 %)
A20: SOUS-TOTAL avec provision pour imprévus | C20: =C18+C19 -> 3556559 | D20: =D18+D19 -> 31176796194
A22: C. Provision pour retards de calendrier (nouvelle demande)
A23: Provision pour retards de calendrier | B23: (Masse salariale + Coordination) ÷ durée × mois de retard | C23: =ROUND((RH!D33+C11)/DUREE_PROJET_MOIS*MOIS_RETARD,0) -> 145217 | D23: =C23*FX_RATE -> 1272972222 | E23: Couvre des mois supplémentaires de salaires et de coordination en cas de glissement de calendrier — durée et nb de mois modifiables en Hypothèses
A25: BUDGET TOTAL DU PROJET (toutes provisions incluses) | C25: =C20+C23 -> 3701776 | D25: =D20+D23 -> 32449768416
A27: Méthode : les postes A sont dérivés du chiffrage réel de la phase pilote de Kaloum (facteur d'échelle ou multiplicateur semi-fixe).
A28: Les postes B chiffrent le coût additionnel du renfort demandé (main d'œuvre × 3, équipements × 2) au-delà de ce qui est déjà
A29: financé dans les postes A. Le poste C provisionne un glissement de calendrier de 2 mois (modifiable) sur la masse salariale et
A30: la coordination. Modifier n'importe quelle hypothèse recalcule automatiquement l'ensemble du budget.

Sheet RH
A1: Ressources humaines — phase d'extension à Dixinn
A3: 9.1. Équipe de coordination et technique
A4: Poste | B4: Effectif Kaloum (référence) | C4: Multiplicateur | D4: Effectif Dixinn | E4: Profil recherché
A5: Chef de projet | B5: 1 | C5: 1 | D5: =ROUND(B5*C5,0) -> 1 | E5: Ingénieur urbaniste / aménagement du territoire, expérience en gestion de projet
A6: Responsable SIG / géomaticien en chef | B6: 1 | C6: 1 | D6: =ROUND(B6*C6,0) -> 1 | E6: Pilotage de la méthodologie cartographique et de la base de données
A7: Techniciens SIG / cartographes | B7: 4 | C7: 1.5 | D7: =ROUND(B7*C7,0) -> 6 | E7: Traitement de l'imagerie, production des cartes, contrôle qualité
A8: Développeurs informatiques (base de données / portail) | B8: 2 | C8: 0.5 | D8: =ROUND(B8*C8,0) -> 1 | E8: Adaptation et maintenance du système SIG déjà développé pour Kaloum
A9: Chefs d'équipe de terrain (superviseurs) | B9: 3 | C9: 1.6667 | D9: =ROUND(B9*C9*MULT_MO,0) -> 15 | E9: Encadrement des enquêteurs, contrôle qualité terrain — effectif × facteur de renfort main d'œuvre (Hypothèses)
A11: 9.2. Équipe de terrain (recrutement temporaire, ~12 à 15 mois)
A12: Poste | B12: Effectif Kaloum (référence) | C12: Multiplicateur | D12: Effectif Dixinn | E12: Profil recherché
A13: Agents enquêteurs (numérotation + relevés GPS) | B13: 14 | C13: 2.2857 | D13: =ROUND(B13*C13*MULT_MO,0) -> 96 | E13: Niveau bac+2 ou expérience en enquêtes de terrain — effectif × facteur de renfort main d'œuvre (Hypothèses)
A14: Agents de sensibilisation communautaire | B14: 6 | C14: 1.8333 | D14: =ROUND(B14*C14*MULT_MO,0) -> 33 | E14: Liaison avec les chefs de quartiers, médiation avec les habitants — effectif × facteur de renfort main d'œuvre (Hypothèses)
A15: Personnel de renfort / réserve | B15: 4 | C15: 1.75 | D15: =ROUND(B15*C15*MULT_MO,0) -> 21 | E15: Profil polyvalent, mobilisé selon les besoins — effectif × facteur de renfort main d'œuvre (Hypothèses)
A16: (soit en équipes de 2, cf. relevé GPS en binôme)
A18: 9.3. Consultants ponctuels et support (effectifs fixes, non proportionnels au bâti)
A19: Poste | B19: Effectif | E19: Nature
A20: Spécialiste toponymie (validation des noms de rues) | B20: 1 | E20: Mission ponctuelle, en lien avec la mairie
A21: Expert juridique / institutionnel | B21: 1 | E21: Mission ponctuelle, appui au cadre légal
A22: Personnel administratif et financier | B22: 2 | E22: Comptable / gestionnaire, assistant administratif
A23: Chauffeurs / logistique | B23: 2 | E23: Postes permanents pour la durée du projet
A24: Équipe de pose de la signalétique (sous-traitée, coût déjà inclus dans le poste « signalétique »)
A26: Synthèse effectifs et masse salariale
A27: Effectif total mobilisé | D27: =SUM(D5:D9)+SUM(D13:D15)+SUM(B20:B23) -> 180
A28: Référence masse salariale — Kaloum
A29: Masse salariale Kaloum (référence, GNF) | B29: 1600000000 | E29: ≈ 183 000 $ pour la phase pilote de Kaloum
A30: Effectif total Kaloum (référence) | B30: 39
A32: Masse salariale estimée — Dixinn (GNF) | D32: =ROUND(B29/B30*D27,0) -> 7384615385
A33: Masse salariale estimée — Dixinn (USD) | D33: =ROUND(D32/FX_RATE,0) -> 842416
A35: Les multiplicateurs (colonne bleue) sont modifiables ; les effectifs Dixinn et la masse salariale recalculent automatiquement.

Sheet Équipements
A1: Équipements et signalétique — phase d'extension à Dixinn
A3: 10.1. Équipements à acquérir
A4: Article | B4: Quantité (formule) | C4: Quantité Dixinn | E4: Observation
A5: Récepteurs GPS de précision (sub-métrique) | B5: ROUND(RH!D13/2,0)+RH!D9 | C5: =(ROUND(RH!D13/2,0)+RH!D9)*MULT_EQUIP -> 126 | E5: Un par binôme d'enquêteurs et par superviseur — quantité × facteur de renfort équipements (Hypothèses)
A6: Tablettes de terrain robustes (collecte mobile) | B6: RH!D13 | C6: =RH!D13*MULT_EQUIP -> 192 | E6: Une par agent enquêteur — quantité × facteur de renfort équipements (Hypothèses)
A7: Ordinateurs portables (équipe SIG / bureau) | B7: RH!D7+RH!D8+RH!D5+RH!D6 | C7: =(RH!D7+RH!D8+RH!D5+RH!D6)*MULT_EQUIP -> 18 | E7: Équipe SIG, développeurs, coordination — quantité × facteur de renfort équipements (Hypothèses)
A8: Licences logiciels SIG | C8: 1 | E8: QGIS (libre) possible en base, avec appui technique payant
A9: Véhicules 4x4 / motos (location, 12 mois) | C9: =5*MULT_EQUIP -> 10 | E9: Location préférée à l'achat pour une phase d'extension — quantité × facteur de renfort équipements (Hypothèses)
A10: Plaques de numérotation des bâtiments | B10: PLAQUES_BAT | C10: =PLAQUES_BAT -> 42495 | E10: Une par bâtiment recensé, fabrication et gravure
A11: Poteau et plaque de rue — fourniture | B11: POTEAUX | C11: =POTEAUX -> 2890 | E11: Un par intersection × 4 coins
A12: Creusement des trous (main d'œuvre + outillage) | B12: POTEAUX | C12: =POTEAUX -> 2890 | E12: Un trou par poteau, sol sablonneux côtier
A13: Ciment et matériaux du massif d'ancrage | B13: POTEAUX | C13: =POTEAUX -> 2890 | E13: Béton, sable, gravier — massif 30×30×50 cm par poteau
A14: Main d'œuvre de pose et scellement | B14: POTEAUX | C14: =POTEAUX -> 2890 | E14: Installation et finition du poteau et de la plaque
A16: 10.4.5. Coût d'installation par poteau (composantes unitaires, GNF)
A17: Poste | B17: Coût unitaire (GNF) | E17: Détail
A18: Fourniture (poteau acier galvanisé + plaque émaillée) | B18: 575000 | E18: Matériel prêt à poser
A19: Creusement du trou | B19: 30000 | E19: Main d'œuvre + outillage manuel
A20: Ciment et matériaux du massif d'ancrage | B20: 40000 | E20: Béton, sable, gravier (massif 30×30×50 cm)
A21: Main d'œuvre de pose et scellement | B21: 35000 | E21: Mise en place, alignement, finition
A22: TOTAL PAR POTEAU | B22: =SUM(B18:B21) -> 680000
A23: Coût total poteaux (GNF) | B23: =B22*POTEAUX -> 1965200000
A24: Coût total poteaux (USD) | B24: =ROUND(B23/FX_RATE,0) -> 224184
A26: 10.4.3. Devis comparatif par matériau (signalétique complète : plaques bâtiment + poteaux)
A27: Matériau | B27: Coût unitaire relatif (vs plexiglas) | C27: Coût total (USD) | D27: Coût total (GNF) | E27: Avantage principal
A28: Acier émaillé (tout matériel) | B28: 253000 | C28: =ROUND(B28*SCALE,0) -> 554187 | D28: =C28*FX_RATE -> 4858003242 | E28: Durabilité maximale (décennies), résistance aux UV et aux graffitis
A29: Aluminium laqué anti-UV (tout matériel) | B29: 197000 | C29: =ROUND(B29*SCALE,0) -> 431521 | D29: =C29*FX_RATE -> 3782713086 | E29: Meilleur équilibre coût/durabilité, léger à poser
A30: Plexiglas (tout matériel) | B30: 130000 | C30: =ROUND(B30*SCALE,0) -> 284760 | D30: =C30*FX_RATE -> 2496206160 | E30: Coût d'achat le plus bas, impression numérique nette
A31: Colonne B = coût de référence Kaloum (à titre de comparaison entre matériaux) ; colonne C = mis à l'échelle de Dixinn.
A33: Toutes les quantités marquées en formule recalculent automatiquement à partir des feuilles Hypothèses et RH.
